<?xml version="1.0" ?>
<!-- =================================================================================== -->
<!-- |    This document was autogenerated by xacro from softhands.urdf.xacro           | -->
<!-- |    EDITING THIS FILE BY HAND IS NOT RECOMMENDED                                 | -->
<!-- =================================================================================== -->
<!-- 
 *  Software License Agreement: BSD 3-Clause License
 *
 * Copyright (c) 2021, NMMI
 * All rights reserved.
 *
 * Redistribution and use in source and binary forms, with or without
 * modification, are permitted provided that the following conditions are met:
 *
 * Redistributions of source code must retain the above copyright notice, this
 * list of conditions and the following disclaimer.
 *
 * Redistributions in binary form must reproduce the above copyright notice,
 * this list of conditions and the following disclaimer in the documentation
 * and/or other materials provided with the distribution.
 *
 * Neither the name of the copyright holder nor the names of its
 * contributors may be used to endorse or promote products derived from
 * this software without specific prior written permission.
 *
 * THIS SOFTWARE IS PROVIDED BY THE COPYRIGHT HOLDERS AND CONTRIBUTORS "AS IS"
 * AND ANY EXPRESS OR IMPLIED WARRANTIES, INCLUDING, BUT NOT LIMITED TO, THE
 * IMPLIED WARRANTIES OF MERCHANTABILITY AND FITNESS FOR A PARTICULAR PURPOSE ARE
 * DISCLAIMED. IN NO EVENT SHALL THE COPYRIGHT HOLDER OR CONTRIBUTORS BE LIABLE
 * FOR ANY DIRECT, INDIRECT, INCIDENTAL, SPECIAL, EXEMPLARY, OR CONSEQUENTIAL
 * DAMAGES (INCLUDING, BUT NOT LIMITED TO, PROCUREMENT OF SUBSTITUTE GOODS OR
 * SERVICES; LOSS OF USE, DATA, OR PROFITS; OR BUSINESS INTERRUPTION) HOWEVER
 * CAUSED AND ON ANY THEORY OF LIABILITY, WHETHER IN CONTRACT, STRICT LIABILITY,
 * OR TORT (INCLUDING NEGLIGENCE OR OTHERWISE) ARISING IN ANY WAY OUT OF THE USE
 * OF THIS SOFTWARE, EVEN IF ADVISED OF THE POSSIBILITY OF SUCH DAMAGE.
 *
 * \file      test_SHs_v2.urdf.xacro
 *
 * \author       _Centro di Ricerca "E.Piaggio"_
 * \author       _Istituto Italiano di Tecnologia, Soft Robotics for Human Cooperation and Rehabilitation Lab_
 *
-->
<robot name="softhand">

  <!-- directives for MuJoCo .xml conversion -->
  <mujoco>
    <compiler 
    meshdir="/home/esguerri/SoftHand/src/SoftHand-Plugin/softhands_description/meshes/v3/right" 
    balanceinertia="true" 
    discardvisual="false" 
    fusestatic="true"
    strippath="true"/>
  </mujoco>

  <material name="qbhand/optional">
    <color rgba="0.0 0.5 0.8 1.0"/>
  </material>
  <material name="qbhand/base">
    <color rgba="0.35 0.35 0.35 1.0"/>
  </material>
  <material name="qbhand/palm">
    <color rgba="0.35 0.35 0.35 1.0"/>
  </material>
  <material name="qbhand/knuckle">
    <color rgba="0.35 0.35 0.35 1.0"/>
  </material>
  <material name="qbhand/proximal">
    <color rgba="0.35 0.35 0.35 1.0"/>
  </material>
  <material name="qbhand/middle">
    <color rgba="0.35 0.35 0.35 1.0"/>
  </material>
  <material name="qbhand/distal">
    <color rgba="0.35 0.35 0.35 1.0"/>
  </material>
  <material name="qbhand/default">
    <color rgba="0.35 0.35 0.35 1.0"/>
  </material>
  <!-- If you are using only the hand -->
  <link name="world"/>
  <!-- IF VERSION == 1_wide -->
  <!-- IF VERSION == v3 -->
  <!-- <xacro:v3
				side="left"
				parent="world" 
				position="0 -0.2 0.02" 
				orientation="${orientation}" 
				fixed_hands="false">
			</xacro:v1_wide> -->
  <gazebo>
    <plugin filename="libsofthand_mimic_plugin.so" name="synergy_plugin">
      <namespace>right_hand_v3</namespace>
      <operation_mode>0</operation_mode>
      <spring_k>5</spring_k>
      <wide>False</wide>
      <r_finger>0.0033</r_finger>
      <R_pulley>0.0053</R_pulley>
      <n_param>0.058</n_param>
      <synS_thumb_j1>3</synS_thumb_j1>
      <synS_thumb_j2>1.2</synS_thumb_j2>
      <synS_thumb_j3>1.2</synS_thumb_j3>
      <k_thumb_j1>0.8</k_thumb_j1>
      <k_thumb_j2>0.8</k_thumb_j2>
      <k_thumb_j3>1.6</k_thumb_j3>
      <synS_index_j1>-0.3</synS_index_j1>
      <synS_index_j2>1.57</synS_index_j2>
      <synS_index_j3>1.25</synS_index_j3>
      <synS_index_j4>0.8</synS_index_j4>
      <k_index_j1>0.15</k_index_j1>
      <k_index_j2>0.5</k_index_j2>
      <k_index_j3>0.5</k_index_j3>
      <k_index_j4>0.5</k_index_j4>
      <synS_middle_j1>0</synS_middle_j1>
      <synS_middle_j2>1.57</synS_middle_j2>
      <synS_middle_j3>1.25</synS_middle_j3>
      <synS_middle_j4>1.25</synS_middle_j4>
      <k_middle_j1>0.15</k_middle_j1>
      <k_middle_j2>0.5</k_middle_j2>
      <k_middle_j3>0.5</k_middle_j3>
      <k_middle_j4>0.5</k_middle_j4>
      <synS_ring_j1>0</synS_ring_j1>
      <synS_ring_j2>1.57</synS_ring_j2>
      <synS_ring_j3>1.0</synS_ring_j3>
      <synS_ring_j4>1.0</synS_ring_j4>
      <k_ring_j1>0.15</k_ring_j1>
      <k_ring_j2>0.5</k_ring_j2>
      <k_ring_j3>0.5</k_ring_j3>
      <k_ring_j4>0.5</k_ring_j4>
      <synS_little_j1>0.1</synS_little_j1>
      <synS_little_j2>1.57</synS_little_j2>
      <synS_little_j3>1.25</synS_little_j3>
      <synS_little_j4>1.0</synS_little_j4>
      <k_little_j1>0.15</k_little_j1>
      <k_little_j2>0.5</k_little_j2>
      <k_little_j3>0.5</k_little_j3>
      <k_little_j4>0.5</k_little_j4>
      <!-- Palm thumb -->
      <synS_palm_j1>1.57</synS_palm_j1>
      <k_palm_j1>0.5</k_palm_j1>
      <k_palm_j1_mimic>0.5</k_palm_j1_mimic>
      <!-- Palm little -->
      <synS_palm_j2>1.57</synS_palm_j2>
      <k_palm_j2>0.5</k_palm_j2>
      <k_palm_j2_mimic>0.5</k_palm_j2_mimic>
    </plugin>
  </gazebo>
  <joint name="right_hand_v3_palm_joint" type="fixed">
    <origin rpy="1.57 0 0" xyz="0 0 0.2"/>
    <parent link="world"/>
    <child link="right_hand_v3_palm_link"/>
  </joint>
  <link name="right_hand_v3_palm_link">
    <inertial>
      <origin rpy="0 0 0" xyz="0.005 -4.037e-2 0.01214"/>
      <mass value="2.27e-1"/>
      <inertia ixx="1.14e-4" ixy="4.47e-6" ixz="-3.04e-6" iyy="7e-5" iyz="2.87e-6" izz="1.608e-4"/>
    </inertial>
    <visual>
      <origin rpy="0 0 0" xyz="0 0 0"/>
      <geometry>
        <mesh filename="package://softhands_description/meshes/v3/right/palm_pinch.stl" scale="0.001 0.001 0.001"/>
      </geometry>
      <material name="qbhand/palm"/>
    </visual>
    <collision>
      <origin rpy="0 0 0" xyz="0 0 0"/>
      <geometry>
        <mesh filename="package://softhands_description/meshes/v3/right/palm_pinch_collision.stl" scale="0.001 0.001 0.001"/>
      </geometry>
    </collision>
  </link>
  <gazebo reference="right_hand_v3_palm_link">
    <material>Gazebo/Grey</material>
    <selfCollide>0</selfCollide>
  </gazebo>
  <!-- Proximal JOINT -->
  <joint name="right_hand_v3_thumb_knuckle_joint" type="revolute">
    <origin rpy="1.5707963 0 2.5307278" xyz="-0.0315281 -0.0276566 -0.0024"/>
    <parent link="right_hand_v3_palm_link"/>
    <child link="right_hand_v3_thumb_knuckle_link"/>
    <axis xyz="0 0 -1"/>
    <limit effort="30" lower="0.0" upper="1.57" velocity="10.0"/>
    <dynamics damping="0.05" friction="0.1"/>
  </joint>
  <!-- LINK -->
  <link name="right_hand_v3_thumb_knuckle_link">
    <inertial>
      <origin rpy="0 0 0" xyz="7.3027049e-03 -2.0974289e-03 -1.9252360e-04"/>
      <mass value="0.0040027562"/>
      <inertia ixx="7.9539066e-08" ixy="4.516365e-08" ixz="-1.9083998e-10" iyy="2.6188505e-07" iyz="-7.2188796e-11" izz="2.7271392e-07"/>
    </inertial>
    <visual>
      <origin rpy="0 0 0" xyz="0 0 0"/>
      <geometry>
        <mesh filename="package://softhands_description/meshes/v3/right/ph_thumb.stl" scale="0.001 0.001 0.001"/>
      </geometry>
      <material name="qbhand/knuckle"/>
    </visual>
    <collision>
      <origin rpy="0 0 0" xyz="0 0 0"/>
      <geometry>
        <mesh filename="package://softhands_description/meshes/v3/right/ph_thumb_collision.stl" scale="0.001 0.001 0.001"/>
      </geometry>
    </collision>
  </link>
  <!-- GAZEBO REF -->
  <gazebo reference="right_hand_v3_thumb_knuckle_link">
    <material>Gazebo/Grey</material>
    <selfCollide>0</selfCollide>
  </gazebo>
  <!-- GAZEBO REF -->
  <gazebo reference="right_hand_v3_thumb_knuckle_joint">
    <implicitSpringDamper>true</implicitSpringDamper>
    <springStiffness>0.4</springStiffness>
    <springReference>0</springReference>
  </gazebo>
  <!-- Inner VIRTUAL JOINT -->
  <joint name="right_hand_v3_thumb_proximal_virtual_joint" type="revolute">
    <axis xyz="0 0 -1"/>
    <origin rpy="-1.5707963 0 0" xyz="16.5e-03 -4.2e-03 0"/>
    <parent link="right_hand_v3_thumb_knuckle_link"/>
    <child link="right_hand_v3_thumb_proximal_virtual_link"/>
    <limit effort="30" lower="0.0" upper="0.785398" velocity="10.0"/>
    <dynamics damping="0.05" friction="0.1"/>
  </joint>
  <!-- VIRTUAL LINK -->
  <link name="right_hand_v3_thumb_proximal_virtual_link">
    <inertial>
      <origin rpy="0 0 0" xyz="0 0 0"/>
      <mass value="0.0034433482"/>
      <inertia ixx="5.9259154e-08" ixy="4.7090997e-09" ixz="0" iyy="4.384944e-07" iyz="0" izz="4.5043748e-07"/>
    </inertial>
  </link>
  <!-- Outer JOINT -->
  <joint name="right_hand_v3_thumb_proximal_joint" type="revolute">
    <axis xyz="0 0 -1"/>
    <origin rpy="0 0 0" xyz="10e-03 0 0"/>
    <parent link="right_hand_v3_thumb_proximal_virtual_link"/>
    <child link="right_hand_v3_thumb_proximal_link"/>
    <limit effort="30" lower="0.0" upper="0.785398" velocity="10.0"/>
    <dynamics damping="0.05" friction="0.1"/>
  </joint>
  <!-- LINK -->
  <link name="right_hand_v3_thumb_proximal_link">
    <inertial>
      <mass value="0.0034433482"/>
      <inertia ixx="5.9259154e-08" ixy="4.7090997e-09" ixz="0" iyy="4.384944e-07" iyz="0" izz="4.5043748e-07"/>
      <origin rpy="0 0 0" xyz="8.2958878e-03 1.4867666e-04 0"/>
    </inertial>
    <visual>
      <origin rpy="0 0 0" xyz="0 0 0"/>
      <geometry>
        <mesh filename="package://softhands_description/meshes/v3/right/ph_proximal.stl" scale="0.001 0.001 0.001"/>
      </geometry>
      <material name="qbhand/palm"/>
    </visual>
    <collision>
      <origin rpy="0 0 0" xyz="0 0 0"/>
      <geometry>
        <mesh filename="package://softhands_description/meshes/v3/right/ph_proximal_collision.stl" scale="0.001 0.001 0.001"/>
      </geometry>
    </collision>
  </link>
  <!-- GAZEBO REF -->
  <gazebo reference="right_hand_v3_thumb_proximal_link">
    <material>Gazebo/Grey</material>
    <selfCollide>0</selfCollide>
  </gazebo>
  <!-- GAZEBO REF -->
  <gazebo reference="right_hand_v3_thumb_proximal_virtual_link">
    <material>Gazebo/Grey</material>
    <selfCollide>0</selfCollide>
  </gazebo>
  <!-- GAZEBO REF -->
  <gazebo reference="right_hand_v3_thumb_proximal_joint">
    <implicitSpringDamper>true</implicitSpringDamper>
    <springStiffness>0.4</springStiffness>
    <springReference>0</springReference>
  </gazebo>
  <!-- GAZEBO REF -->
  <gazebo reference="right_hand_v3_thumb_proximal_virtual_joint">
    <implicitSpringDamper>true</implicitSpringDamper>
    <springStiffness>0.4</springStiffness>
    <springReference>0</springReference>
  </gazebo>
  <!-- Inner VIRTUAL JOINT -->
  <joint name="right_hand_v3_thumb_distal_virtual_joint" type="revolute">
    <axis xyz="0 0 -1"/>
    <origin rpy="0 0 0" xyz="16e-03 0 0"/>
    <parent link="right_hand_v3_thumb_proximal_link"/>
    <child link="right_hand_v3_thumb_distal_virtual_link"/>
    <limit effort="30" lower="0.0" upper="0.785398" velocity="10.0"/>
    <dynamics damping="0.05" friction="0.1"/>
  </joint>
  <!-- VIRTUAL LINK -->
  <link name="right_hand_v3_thumb_distal_virtual_link">
    <inertial>
      <origin rpy="0 0 0" xyz="0 0 0"/>
      <mass value="0.0024034657"/>
      <inertia ixx="2.9487712e-08" ixy="5.9094481e-10" ixz="1.3105246e-10" iyy="6.1647801e-08" iyz="4.9617465e-11" izz="5.8551334e-08"/>
    </inertial>
  </link>
  <!-- Outer JOINT -->
  <joint name="right_hand_v3_thumb_distal_joint" type="revolute">
    <axis xyz="0 0 -1"/>
    <origin rpy="0 0 0" xyz="10e-03 0 0"/>
    <parent link="right_hand_v3_thumb_distal_virtual_link"/>
    <child link="right_hand_v3_thumb_distal_link"/>
    <limit effort="30" lower="0.0" upper="0.785398" velocity="10.0"/>
    <dynamics damping="0.05" friction="0.1"/>
  </joint>
  <!-- LINK -->
  <link name="right_hand_v3_thumb_distal_link">
    <inertial>
      <mass value="0.0024034657"/>
      <inertia ixx="2.9487712e-08" ixy="5.9094481e-10" ixz="1.3105246e-10" iyy="6.1647801e-08" iyz="4.9617465e-11" izz="5.8551334e-08"/>
      <origin rpy="0 0 0" xyz="2.3379604e-03 5.3580065e-04 -4.5070160e-04"/>
    </inertial>
    <visual>
      <origin rpy="0 0 0" xyz="0 0 0"/>
      <geometry>
        <mesh filename="package://softhands_description/meshes/v3/right/ph_distal.stl" scale="0.001 0.001 0.001"/>
      </geometry>
      <material name="qbhand/palm"/>
    </visual>
    <collision>
      <origin rpy="0 0 0" xyz="0 0 0"/>
      <geometry>
        <mesh filename="package://softhands_description/meshes/v3/right/ph_distal_collision.stl" scale="0.001 0.001 0.001"/>
      </geometry>
    </collision>
  </link>
  <!-- GAZEBO REF -->
  <gazebo reference="right_hand_v3_thumb_distal_link">
    <material>Gazebo/Grey</material>
    <selfCollide>0</selfCollide>
  </gazebo>
  <!-- GAZEBO REF -->
  <gazebo reference="right_hand_v3_thumb_distal_virtual_link">
    <material>Gazebo/Grey</material>
    <selfCollide>0</selfCollide>
  </gazebo>
  <!-- GAZEBO REF -->
  <gazebo reference="right_hand_v3_thumb_distal_joint">
    <implicitSpringDamper>true</implicitSpringDamper>
    <springStiffness>0.4</springStiffness>
    <springReference>0</springReference>
  </gazebo>
  <!-- GAZEBO REF -->
  <gazebo reference="right_hand_v3_thumb_distal_virtual_joint">
    <implicitSpringDamper>true</implicitSpringDamper>
    <springStiffness>0.4</springStiffness>
    <springReference>0</springReference>
  </gazebo>
  <!-- Proximal JOINT -->
  <joint name="right_hand_v3_index_knuckle_joint" type="revolute">
    <origin rpy="0 0 1.7453293" xyz="-20e-03 0 6.0267000e-03"/>
    <parent link="right_hand_v3_palm_link"/>
    <child link="right_hand_v3_index_knuckle_link"/>
    <axis xyz="0 0 -1"/>
    <limit effort="30" lower="-0.524" upper="0.524" velocity="10.0"/>
    <dynamics damping="0.05" friction="0.1"/>
  </joint>
  <!-- LINK -->
  <link name="right_hand_v3_index_knuckle_link">
    <inertial>
      <mass value="0.0029531895"/>
      <inertia ixx="4.9114511e-08" ixy="2.4336199e-08" ixz="1.133675e-09" iyy="1.6520715e-07" iyz="-4.697203e-10" izz="1.7172503e-07"/>
      <origin rpy="0 0 0" xyz="8.2672528e-03 -2.7479334e-03 6.3742013e-05"/>
    </inertial>
    <visual>
      <origin rpy="0 0 0" xyz="0 0 0"/>
      <geometry>
        <mesh filename="package://softhands_description/meshes/v3/right/ph_index_knuckle.stl" scale="0.001 0.001 0.001"/>
      </geometry>
      <material name="qbhand/palm"/>
    </visual>
    <collision>
      <origin rpy="0 0 0" xyz="0 0 0"/>
      <geometry>
        <mesh filename="package://softhands_description/meshes/v3/right/ph_index_knuckle_collision.stl" scale="0.001 0.001 0.001"/>
      </geometry>
    </collision>
  </link>
  <!-- GAZEBO REF -->
  <gazebo reference="right_hand_v3_index_knuckle_link">
    <material>Gazebo/Grey</material>
    <selfCollide>0</selfCollide>
  </gazebo>
  <!-- GAZEBO REF -->
  <gazebo reference="right_hand_v3_index_knuckle_joint">
    <implicitSpringDamper>true</implicitSpringDamper>
    <springStiffness>0.8</springStiffness>
    <springReference>0</springReference>
  </gazebo>
  <!-- Inner VIRTUAL JOINT -->
  <joint name="right_hand_v3_index_proximal_virtual_joint" type="revolute">
    <axis xyz="0 0 -1"/>
    <origin rpy="1.5707963 0 0" xyz="15e-03 -3.7e-03 0"/>
    <parent link="right_hand_v3_index_knuckle_link"/>
    <child link="right_hand_v3_index_proximal_virtual_link"/>
    <limit effort="30" lower="0.0" upper="0.785398" velocity="10.0"/>
    <dynamics damping="0.05" friction="0.1"/>
  </joint>
  <!-- VIRTUAL LINK -->
  <link name="right_hand_v3_index_proximal_virtual_link">
    <inertial>
      <origin rpy="0 0 0" xyz="0 0 0"/>
      <mass value="0.0034433482"/>
      <inertia ixx="5.9259154e-08" ixy="4.7090997e-09" ixz="0" iyy="4.384944e-07" iyz="0" izz="4.5043748e-07"/>
    </inertial>
  </link>
  <!-- Outer JOINT -->
  <joint name="right_hand_v3_index_proximal_joint" type="revolute">
    <axis xyz="0 0 -1"/>
    <origin rpy="0 0 0" xyz="10e-03 0 0"/>
    <parent link="right_hand_v3_index_proximal_virtual_link"/>
    <child link="right_hand_v3_index_proximal_link"/>
    <limit effort="30" lower="0.0" upper="0.785398" velocity="10.0"/>
    <dynamics damping="0.05" friction="0.1"/>
  </joint>
  <!-- LINK -->
  <link name="right_hand_v3_index_proximal_link">
    <inertial>
      <mass value="0.0034433482"/>
      <inertia ixx="5.9259154e-08" ixy="4.7090997e-09" ixz="0" iyy="4.384944e-07" iyz="0" izz="4.5043748e-07"/>
      <origin rpy="0 0 0" xyz="8.2958878e-03 1.4867666e-04 0"/>
    </inertial>
    <visual>
      <origin rpy="0 0 0" xyz="0 0 0"/>
      <geometry>
        <mesh filename="package://softhands_description/meshes/v3/right/ph_proximal.stl" scale="0.001 0.001 0.001"/>
      </geometry>
      <material name="qbhand/palm"/>
    </visual>
    <collision>
      <origin rpy="0 0 0" xyz="0 0 0"/>
      <geometry>
        <mesh filename="package://softhands_description/meshes/v3/right/ph_proximal_collision.stl" scale="0.001 0.001 0.001"/>
      </geometry>
    </collision>
  </link>
  <!-- GAZEBO REF -->
  <gazebo reference="right_hand_v3_index_proximal_link">
    <material>Gazebo/Grey</material>
    <selfCollide>0</selfCollide>
  </gazebo>
  <!-- GAZEBO REF -->
  <gazebo reference="right_hand_v3_index_proximal_virtual_link">
    <material>Gazebo/Grey</material>
    <selfCollide>0</selfCollide>
  </gazebo>
  <!-- GAZEBO REF -->
  <gazebo reference="right_hand_v3_index_proximal_joint">
    <implicitSpringDamper>true</implicitSpringDamper>
    <springStiffness>0.4</springStiffness>
    <springReference>0</springReference>
  </gazebo>
  <!-- GAZEBO REF -->
  <gazebo reference="right_hand_v3_index_proximal_virtual_joint">
    <implicitSpringDamper>true</implicitSpringDamper>
    <springStiffness>0.4</springStiffness>
    <springReference>0</springReference>
  </gazebo>
  <!-- Inner VIRTUAL JOINT -->
  <joint name="right_hand_v3_index_middle_virtual_joint" type="revolute">
    <axis xyz="0 0 -1"/>
    <origin rpy="0 0 0" xyz="16e-03 0 0"/>
    <parent link="right_hand_v3_index_proximal_link"/>
    <child link="right_hand_v3_index_middle_virtual_link"/>
    <limit effort="30" lower="0.0" upper="0.785398" velocity="10.0"/>
    <dynamics damping="0.05" friction="0.1"/>
  </joint>
  <!-- VIRTUAL LINK -->
  <link name="right_hand_v3_index_middle_virtual_link">
    <inertial>
      <origin rpy="0 0 0" xyz="0 0 0"/>
      <mass value="0.0034433482"/>
      <inertia ixx="5.9259154e-08" ixy="4.7090997e-09" ixz="0" iyy="4.384944e-07" iyz="0" izz="4.5043748e-07"/>
    </inertial>
  </link>
  <!-- Outer JOINT -->
  <joint name="right_hand_v3_index_middle_joint" type="revolute">
    <axis xyz="0 0 -1"/>
    <origin rpy="0 0 0" xyz="10e-03 0 0"/>
    <parent link="right_hand_v3_index_middle_virtual_link"/>
    <child link="right_hand_v3_index_middle_link"/>
    <limit effort="30" lower="0.0" upper="0.785398" velocity="10.0"/>
    <dynamics damping="0.05" friction="0.1"/>
  </joint>
  <!-- LINK -->
  <link name="right_hand_v3_index_middle_link">
    <inertial>
      <mass value="0.0034433482"/>
      <inertia ixx="5.9259154e-08" ixy="4.7090997e-09" ixz="0" iyy="4.384944e-07" iyz="0" izz="4.5043748e-07"/>
      <origin rpy="0 0 0" xyz="8.2958878e-03 1.4867666e-04 0"/>
    </inertial>
    <visual>
      <origin rpy="0 0 0" xyz="0 0 0"/>
      <geometry>
        <mesh filename="package://softhands_description/meshes/v3/right/ph_proximal.stl" scale="0.001 0.001 0.001"/>
      </geometry>
      <material name="qbhand/palm"/>
    </visual>
    <collision>
      <origin rpy="0 0 0" xyz="0 0 0"/>
      <geometry>
        <mesh filename="package://softhands_description/meshes/v3/right/ph_proximal_collision.stl" scale="0.001 0.001 0.001"/>
      </geometry>
    </collision>
  </link>
  <!-- GAZEBO REF -->
  <gazebo reference="right_hand_v3_index_middle_link">
    <material>Gazebo/Grey</material>
    <selfCollide>0</selfCollide>
  </gazebo>
  <!-- GAZEBO REF -->
  <gazebo reference="right_hand_v3_index_middle_virtual_link">
    <material>Gazebo/Grey</material>
    <selfCollide>0</selfCollide>
  </gazebo>
  <!-- GAZEBO REF -->
  <gazebo reference="right_hand_v3_index_middle_joint">
    <implicitSpringDamper>true</implicitSpringDamper>
    <springStiffness>0.4</springStiffness>
    <springReference>0</springReference>
  </gazebo>
  <!-- GAZEBO REF -->
  <gazebo reference="right_hand_v3_index_middle_virtual_joint">
    <implicitSpringDamper>true</implicitSpringDamper>
    <springStiffness>0.4</springStiffness>
    <springReference>0</springReference>
  </gazebo>
  <!-- Inner VIRTUAL JOINT -->
  <joint name="right_hand_v3_index_distal_virtual_joint" type="revolute">
    <axis xyz="0 0 -1"/>
    <origin rpy="0 0 0" xyz="16e-03 0 0"/>
    <parent link="right_hand_v3_index_middle_link"/>
    <child link="right_hand_v3_index_distal_virtual_link"/>
    <limit effort="30" lower="0.0" upper="0.785398" velocity="10.0"/>
    <dynamics damping="0.05" friction="0.1"/>
  </joint>
  <!-- VIRTUAL LINK -->
  <link name="right_hand_v3_index_distal_virtual_link">
    <inertial>
      <origin rpy="0 0 0" xyz="0 0 0"/>
      <mass value="0.0024034657"/>
      <inertia ixx="2.9487712e-08" ixy="5.9094481e-10" ixz="1.3105246e-10" iyy="6.1647801e-08" iyz="4.9617465e-11" izz="5.8551334e-08"/>
    </inertial>
  </link>
  <!-- Outer JOINT -->
  <joint name="right_hand_v3_index_distal_joint" type="revolute">
    <axis xyz="0 0 -1"/>
    <origin rpy="0 0 0" xyz="10e-03 -0.000348650e-03 0.5e-03"/>
    <parent link="right_hand_v3_index_distal_virtual_link"/>
    <child link="right_hand_v3_index_distal_link"/>
    <limit effort="30" lower="0.0" upper="0.785398" velocity="10.0"/>
    <dynamics damping="0.05" friction="0.1"/>
  </joint>
  <!-- LINK -->
  <link name="right_hand_v3_index_distal_link">
    <inertial>
      <mass value="0.0024034657"/>
      <inertia ixx="2.9487712e-08" ixy="5.9094481e-10" ixz="1.3105246e-10" iyy="6.1647801e-08" iyz="4.9617465e-11" izz="5.8551334e-08"/>
      <origin rpy="0 0 0" xyz="2.3379604e-03 5.3580065e-04 -4.5070160e-04"/>
    </inertial>
    <visual>
      <origin rpy="0 0 0" xyz="0 0 0"/>
      <geometry>
        <mesh filename="package://softhands_description/meshes/v3/right/ph_distal.stl" scale="0.001 0.001 0.001"/>
      </geometry>
      <material name="qbhand/palm"/>
    </visual>
    <collision>
      <origin rpy="0 0 0" xyz="0 0 0"/>
      <geometry>
        <mesh filename="package://softhands_description/meshes/v3/right/ph_distal_collision.stl" scale="0.001 0.001 0.001"/>
      </geometry>
    </collision>
  </link>
  <!-- GAZEBO REF -->
  <gazebo reference="right_hand_v3_index_distal_link">
    <material>Gazebo/Grey</material>
    <selfCollide>0</selfCollide>
  </gazebo>
  <!-- GAZEBO REF -->
  <gazebo reference="right_hand_v3_index_distal_virtual_link">
    <material>Gazebo/Grey</material>
    <selfCollide>0</selfCollide>
  </gazebo>
  <!-- GAZEBO REF -->
  <gazebo reference="right_hand_v3_index_distal_joint">
    <implicitSpringDamper>true</implicitSpringDamper>
    <springStiffness>0.4</springStiffness>
    <springReference>0</springReference>
  </gazebo>
  <!-- GAZEBO REF -->
  <gazebo reference="right_hand_v3_index_distal_virtual_joint">
    <implicitSpringDamper>true</implicitSpringDamper>
    <springStiffness>0.4</springStiffness>
    <springReference>0</springReference>
  </gazebo>
  <!-- Proximal JOINT -->
  <joint name="right_hand_v3_middle_knuckle_joint" type="revolute">
    <origin rpy="0 0 1.5707963" xyz="0 0 6.3e-03"/>
    <parent link="right_hand_v3_palm_link"/>
    <child link="right_hand_v3_middle_knuckle_link"/>
    <axis xyz="0 0 -1"/>
    <limit effort="30" lower="-0.524" upper="0.524" velocity="10.0"/>
    <dynamics damping="0.05" friction="0.1"/>
  </joint>
  <!-- LINK -->
  <link name="right_hand_v3_middle_knuckle_link">
    <inertial>
      <mass value="0.0031680581"/>
      <inertia ixx="5.0879185e-08" ixy="0" ixz="1.0613266e-09" iyy="1.6958878e-07" iyz="9.1776943e-11" izz="1.7374086e-07"/>
      <origin rpy="0 0 0" xyz="8.0072955e-03 -7.0168939e-04 -2.2093465e-04"/>
    </inertial>
    <visual>
      <origin rpy="0 0 0" xyz="0 0 0"/>
      <geometry>
        <mesh filename="package://softhands_description/meshes/v3/right/ph_middle_knuckle.stl" scale="0.001 0.001 0.001"/>
      </geometry>
      <material name="qbhand/palm"/>
    </visual>
    <collision>
      <origin rpy="0 0 0" xyz="0 0 0"/>
      <geometry>
        <mesh filename="package://softhands_description/meshes/v3/right/ph_middle_knuckle_collision.stl" scale="0.001 0.001 0.001"/>
      </geometry>
    </collision>
  </link>
  <!-- GAZEBO REF -->
  <gazebo reference="right_hand_v3_middle_knuckle_link">
    <material>Gazebo/Grey</material>
    <selfCollide>0</selfCollide>
  </gazebo>
  <!-- GAZEBO REF -->
  <gazebo reference="right_hand_v3_middle_knuckle_joint">
    <implicitSpringDamper>true</implicitSpringDamper>
    <springStiffness>0.8</springStiffness>
    <springReference>0</springReference>
  </gazebo>
  <!-- Inner VIRTUAL JOINT -->
  <joint name="right_hand_v3_middle_proximal_virtual_joint" type="revolute">
    <axis xyz="0 0 -1"/>
    <origin rpy="1.5707963 0 0" xyz="15e-03 0 -0.273297e-03"/>
    <parent link="right_hand_v3_middle_knuckle_link"/>
    <child link="right_hand_v3_middle_proximal_virtual_link"/>
    <limit effort="30" lower="0.0" upper="0.785398" velocity="10.0"/>
    <dynamics damping="0.05" friction="0.1"/>
  </joint>
  <!-- VIRTUAL LINK -->
  <link name="right_hand_v3_middle_proximal_virtual_link">
    <inertial>
      <origin rpy="0 0 0" xyz="0 0 0"/>
      <mass value="0.0046375462"/>
      <inertia ixx="7.1982535e-08" ixy="3.4059376e-09" ixz="0" iyy="4.1658521e-07" iyz="0" izz="4.2600955e-07"/>
    </inertial>
  </link>
  <!-- Outer JOINT -->
  <joint name="right_hand_v3_middle_proximal_joint" type="revolute">
    <axis xyz="0 0 -1"/>
    <origin rpy="0 0 0" xyz="10e-03 0 0"/>
    <parent link="right_hand_v3_middle_proximal_virtual_link"/>
    <child link="right_hand_v3_middle_proximal_link"/>
    <limit effort="30" lower="0.0" upper="0.785398" velocity="10.0"/>
    <dynamics damping="0.05" friction="0.1"/>
  </joint>
  <!-- LINK -->
  <link name="right_hand_v3_middle_proximal_link">
    <inertial>
      <mass value="0.0046375462"/>
      <inertia ixx="7.1982535e-08" ixy="3.4059376e-09" ixz="0" iyy="4.1658521e-07" iyz="0" izz="4.2600955e-07"/>
      <origin rpy="0 0 0" xyz="8.8492117e-03 2.8838342e-04 0"/>
    </inertial>
    <visual>
      <origin rpy="0 0 0" xyz="0 0 0"/>
      <geometry>
        <mesh filename="package://softhands_description/meshes/v3/right/ph_proximal_middle.stl" scale="0.001 0.001 0.001"/>
      </geometry>
      <material name="qbhand/palm"/>
    </visual>
    <collision>
      <origin rpy="0 0 0" xyz="0 0 0"/>
      <geometry>
        <mesh filename="package://softhands_description/meshes/v3/right/ph_proximal_middle_collision.stl" scale="0.001 0.001 0.001"/>
      </geometry>
    </collision>
  </link>
  <!-- GAZEBO REF -->
  <gazebo reference="right_hand_v3_middle_proximal_link">
    <material>Gazebo/Grey</material>
    <selfCollide>0</selfCollide>
  </gazebo>
  <!-- GAZEBO REF -->
  <gazebo reference="right_hand_v3_middle_proximal_virtual_link">
    <material>Gazebo/Grey</material>
    <selfCollide>0</selfCollide>
  </gazebo>
  <!-- GAZEBO REF -->
  <gazebo reference="right_hand_v3_middle_proximal_joint">
    <implicitSpringDamper>true</implicitSpringDamper>
    <springStiffness>0.4</springStiffness>
    <springReference>0</springReference>
  </gazebo>
  <!-- GAZEBO REF -->
  <gazebo reference="right_hand_v3_middle_proximal_virtual_joint">
    <implicitSpringDamper>true</implicitSpringDamper>
    <springStiffness>0.4</springStiffness>
    <springReference>0</springReference>
  </gazebo>
  <!-- Inner VIRTUAL JOINT -->
  <joint name="right_hand_v3_middle_middle_virtual_joint" type="revolute">
    <axis xyz="0 0 -1"/>
    <origin rpy="0 0 0" xyz="21e-03 0 0"/>
    <parent link="right_hand_v3_middle_proximal_link"/>
    <child link="right_hand_v3_middle_middle_virtual_link"/>
    <limit effort="30" lower="0.0" upper="0.785398" velocity="10.0"/>
    <dynamics damping="0.05" friction="0.1"/>
  </joint>
  <!-- VIRTUAL LINK -->
  <link name="right_hand_v3_middle_middle_virtual_link">
    <inertial>
      <origin rpy="0 0 0" xyz="0 0 0"/>
      <mass value="0.0046375462"/>
      <inertia ixx="7.1982535e-08" ixy="3.4059376e-09" ixz="0" iyy="4.1658521e-07" iyz="0" izz="4.2600955e-07"/>
    </inertial>
  </link>
  <!-- Outer JOINT -->
  <joint name="right_hand_v3_middle_middle_joint" type="revolute">
    <axis xyz="0 0 -1"/>
    <origin rpy="0 0 0" xyz="10e-03 0 0"/>
    <parent link="right_hand_v3_middle_middle_virtual_link"/>
    <child link="right_hand_v3_middle_middle_link"/>
    <limit effort="30" lower="0.0" upper="0.785398" velocity="10.0"/>
    <dynamics damping="0.05" friction="0.1"/>
  </joint>
  <!-- LINK -->
  <link name="right_hand_v3_middle_middle_link">
    <inertial>
      <mass value="0.0046375462"/>
      <inertia ixx="7.1982535e-08" ixy="3.4059376e-09" ixz="0" iyy="4.1658521e-07" iyz="0" izz="4.2600955e-07"/>
      <origin rpy="0 0 0" xyz="8.8492117e-03 2.8838342e-04 0"/>
    </inertial>
    <visual>
      <origin rpy="0 0 0" xyz="0 0 0"/>
      <geometry>
        <mesh filename="package://softhands_description/meshes/v3/right/ph_proximal_middle.stl" scale="0.001 0.001 0.001"/>
      </geometry>
      <material name="qbhand/palm"/>
    </visual>
    <collision>
      <origin rpy="0 0 0" xyz="0 0 0"/>
      <geometry>
        <mesh filename="package://softhands_description/meshes/v3/right/ph_proximal_middle_collision.stl" scale="0.001 0.001 0.001"/>
      </geometry>
    </collision>
  </link>
  <!-- GAZEBO REF -->
  <gazebo reference="right_hand_v3_middle_middle_link">
    <material>Gazebo/Grey</material>
    <selfCollide>0</selfCollide>
  </gazebo>
  <!-- GAZEBO REF -->
  <gazebo reference="right_hand_v3_middle_middle_virtual_link">
    <material>Gazebo/Grey</material>
    <selfCollide>0</selfCollide>
  </gazebo>
  <!-- GAZEBO REF -->
  <gazebo reference="right_hand_v3_middle_middle_joint">
    <implicitSpringDamper>true</implicitSpringDamper>
    <springStiffness>0.4</springStiffness>
    <springReference>0</springReference>
  </gazebo>
  <!-- GAZEBO REF -->
  <gazebo reference="right_hand_v3_middle_middle_virtual_joint">
    <implicitSpringDamper>true</implicitSpringDamper>
    <springStiffness>0.4</springStiffness>
    <springReference>0</springReference>
  </gazebo>
  <!-- Inner VIRTUAL JOINT -->
  <joint name="right_hand_v3_middle_distal_virtual_joint" type="revolute">
    <axis xyz="0 0 -1"/>
    <origin rpy="0 0 0" xyz="21e-03 0 0"/>
    <parent link="right_hand_v3_middle_middle_link"/>
    <child link="right_hand_v3_middle_distal_virtual_link"/>
    <limit effort="30" lower="0.0" upper="0.785398" velocity="10.0"/>
    <dynamics damping="0.05" friction="0.1"/>
  </joint>
  <!-- VIRTUAL LINK -->
  <link name="right_hand_v3_middle_distal_virtual_link">
    <inertial>
      <origin rpy="0 0 0" xyz="0 0 0"/>
      <mass value="0.0024034657"/>
      <inertia ixx="2.9487712e-08" ixy="5.9094481e-10" ixz="1.3105246e-10" iyy="6.1647801e-08" iyz="4.9617465e-11" izz="5.8551334e-08"/>
    </inertial>
  </link>
  <!-- Outer JOINT -->
  <joint name="right_hand_v3_middle_distal_joint" type="revolute">
    <axis xyz="0 0 -1"/>
    <origin rpy="0 0 0" xyz="10e-03 -0.000348650e-03 0.5e-03"/>
    <parent link="right_hand_v3_middle_distal_virtual_link"/>
    <child link="right_hand_v3_middle_distal_link"/>
    <limit effort="30" lower="0.0" upper="0.785398" velocity="10.0"/>
    <dynamics damping="0.05" friction="0.1"/>
  </joint>
  <!-- LINK -->
  <link name="right_hand_v3_middle_distal_link">
    <inertial>
      <mass value="0.0024034657"/>
      <inertia ixx="2.9487712e-08" ixy="5.9094481e-10" ixz="1.3105246e-10" iyy="6.1647801e-08" iyz="4.9617465e-11" izz="5.8551334e-08"/>
      <origin rpy="0 0 0" xyz="2.3379604e-03 5.3580065e-04 -4.5070160e-04"/>
    </inertial>
    <visual>
      <origin rpy="0 0 0" xyz="0 0 0"/>
      <geometry>
        <mesh filename="package://softhands_description/meshes/v3/right/ph_distal.stl" scale="0.001 0.001 0.001"/>
      </geometry>
      <material name="qbhand/palm"/>
    </visual>
    <collision>
      <origin rpy="0 0 0" xyz="0 0 0"/>
      <geometry>
        <mesh filename="package://softhands_description/meshes/v3/right/ph_distal_collision.stl" scale="0.001 0.001 0.001"/>
      </geometry>
    </collision>
  </link>
  <!-- GAZEBO REF -->
  <gazebo reference="right_hand_v3_middle_distal_link">
    <material>Gazebo/Grey</material>
    <selfCollide>0</selfCollide>
  </gazebo>
  <!-- GAZEBO REF -->
  <gazebo reference="right_hand_v3_middle_distal_virtual_link">
    <material>Gazebo/Grey</material>
    <selfCollide>0</selfCollide>
  </gazebo>
  <!-- GAZEBO REF -->
  <gazebo reference="right_hand_v3_middle_distal_joint">
    <implicitSpringDamper>true</implicitSpringDamper>
    <springStiffness>0.4</springStiffness>
    <springReference>0</springReference>
  </gazebo>
  <!-- GAZEBO REF -->
  <gazebo reference="right_hand_v3_middle_distal_virtual_joint">
    <implicitSpringDamper>true</implicitSpringDamper>
    <springStiffness>0.4</springStiffness>
    <springReference>0</springReference>
  </gazebo>
  <!-- Proximal JOINT -->
  <joint name="right_hand_v3_ring_knuckle_joint" type="revolute">
    <origin rpy="0 0 1.3962638" xyz="20e-03 0 6.02670e-03"/>
    <parent link="right_hand_v3_palm_link"/>
    <child link="right_hand_v3_ring_knuckle_link"/>
    <axis xyz="0 0 -1"/>
    <limit effort="30" lower="-0.524" upper="0.524" velocity="10.0"/>
    <dynamics damping="0.05" friction="0.1"/>
  </joint>
  <!-- LINK -->
  <link name="right_hand_v3_ring_knuckle_link">
    <inertial>
      <mass value="0.0043252792"/>
      <inertia ixx="8.3644527e-08" ixy="-4.5618254e-08" ixz="2.3871797e-09" iyy="2.5669244e-07" iyz="8.8656059e-10" izz="2.4876038e-07"/>
      <origin rpy="0 0 0" xyz="5.6446671e-03 1.8762438e-03 1.1508432e-04"/>
    </inertial>
    <visual>
      <origin rpy="0 0 0" xyz="0 0 0"/>
      <geometry>
        <mesh filename="package://softhands_description/meshes/v3/right/ph_ring_knuckle.stl" scale="0.001 0.001 0.001"/>
      </geometry>
      <material name="qbhand/palm"/>
    </visual>
    <collision>
      <origin rpy="0 0 0" xyz="0 0 0"/>
      <geometry>
        <mesh filename="package://softhands_description/meshes/v3/right/ph_ring_knuckle_collision.stl" scale="0.001 0.001 0.001"/>
      </geometry>
    </collision>
  </link>
  <!-- GAZEBO REF -->
  <gazebo reference="right_hand_v3_ring_knuckle_link">
    <material>Gazebo/Grey</material>
    <selfCollide>0</selfCollide>
  </gazebo>
  <!-- GAZEBO REF -->
  <gazebo reference="right_hand_v3_ring_knuckle_joint">
    <implicitSpringDamper>true</implicitSpringDamper>
    <springStiffness>0.8</springStiffness>
    <springReference>0</springReference>
  </gazebo>
  <!-- Inner VIRTUAL JOINT -->
  <joint name="right_hand_v3_ring_proximal_virtual_joint" type="revolute">
    <axis xyz="0 0 -1"/>
    <origin rpy="1.5707963 0 0" xyz="15e-03 3.7e-03 0"/>
    <parent link="right_hand_v3_ring_knuckle_link"/>
    <child link="right_hand_v3_ring_proximal_virtual_link"/>
    <limit effort="30" lower="0.0" upper="0.785398" velocity="10.0"/>
    <dynamics damping="0.05" friction="0.1"/>
  </joint>
  <!-- VIRTUAL LINK -->
  <link name="right_hand_v3_ring_proximal_virtual_link">
    <inertial>
      <origin rpy="0 0 0" xyz="0 0 0"/>
      <mass value="0.0034433482"/>
      <inertia ixx="5.9259154e-08" ixy="4.7090997e-09" ixz="0" iyy="4.384944e-07" iyz="0" izz="4.5043748e-07"/>
    </inertial>
  </link>
  <!-- Outer JOINT -->
  <joint name="right_hand_v3_ring_proximal_joint" type="revolute">
    <axis xyz="0 0 -1"/>
    <origin rpy="0 0 0" xyz="10e-03 0 0"/>
    <parent link="right_hand_v3_ring_proximal_virtual_link"/>
    <child link="right_hand_v3_ring_proximal_link"/>
    <limit effort="30" lower="0.0" upper="0.785398" velocity="10.0"/>
    <dynamics damping="0.05" friction="0.1"/>
  </joint>
  <!-- LINK -->
  <link name="right_hand_v3_ring_proximal_link">
    <inertial>
      <mass value="0.0034433482"/>
      <inertia ixx="5.9259154e-08" ixy="4.7090997e-09" ixz="0" iyy="4.384944e-07" iyz="0" izz="4.5043748e-07"/>
      <origin rpy="0 0 0" xyz="8.2958878e-03 1.4867666e-04 0"/>
    </inertial>
    <visual>
      <origin rpy="0 0 0" xyz="0 0 0"/>
      <geometry>
        <mesh filename="package://softhands_description/meshes/v3/right/ph_proximal.stl" scale="0.001 0.001 0.001"/>
      </geometry>
      <material name="qbhand/palm"/>
    </visual>
    <collision>
      <origin rpy="0 0 0" xyz="0 0 0"/>
      <geometry>
        <mesh filename="package://softhands_description/meshes/v3/right/ph_proximal_collision.stl" scale="0.001 0.001 0.001"/>
      </geometry>
    </collision>
  </link>
  <!-- GAZEBO REF -->
  <gazebo reference="right_hand_v3_ring_proximal_link">
    <material>Gazebo/Grey</material>
    <selfCollide>0</selfCollide>
  </gazebo>
  <!-- GAZEBO REF -->
  <gazebo reference="right_hand_v3_ring_proximal_virtual_link">
    <material>Gazebo/Grey</material>
    <selfCollide>0</selfCollide>
  </gazebo>
  <!-- GAZEBO REF -->
  <gazebo reference="right_hand_v3_ring_proximal_joint">
    <implicitSpringDamper>true</implicitSpringDamper>
    <springStiffness>0.4</springStiffness>
    <springReference>0</springReference>
  </gazebo>
  <!-- GAZEBO REF -->
  <gazebo reference="right_hand_v3_ring_proximal_virtual_joint">
    <implicitSpringDamper>true</implicitSpringDamper>
    <springStiffness>0.4</springStiffness>
    <springReference>0</springReference>
  </gazebo>
  <!-- Inner VIRTUAL JOINT -->
  <joint name="right_hand_v3_ring_middle_virtual_joint" type="revolute">
    <axis xyz="0 0 -1"/>
    <origin rpy="0 0 0" xyz="16e-03 0 0"/>
    <parent link="right_hand_v3_ring_proximal_link"/>
    <child link="right_hand_v3_ring_middle_virtual_link"/>
    <limit effort="30" lower="0.0" upper="0.785398" velocity="10.0"/>
    <dynamics damping="0.05" friction="0.1"/>
  </joint>
  <!-- VIRTUAL LINK -->
  <link name="right_hand_v3_ring_middle_virtual_link">
    <inertial>
      <origin rpy="0 0 0" xyz="0 0 0"/>
      <mass value="0.0034433482"/>
      <inertia ixx="5.9259154e-08" ixy="4.7090997e-09" ixz="0" iyy="4.384944e-07" iyz="0" izz="4.5043748e-07"/>
    </inertial>
  </link>
  <!-- Outer JOINT -->
  <joint name="right_hand_v3_ring_middle_joint" type="revolute">
    <axis xyz="0 0 -1"/>
    <origin rpy="0 0 0" xyz="10e-03 0 0"/>
    <parent link="right_hand_v3_ring_middle_virtual_link"/>
    <child link="right_hand_v3_ring_middle_link"/>
    <limit effort="30" lower="0.0" upper="0.785398" velocity="10.0"/>
    <dynamics damping="0.05" friction="0.1"/>
  </joint>
  <!-- LINK -->
  <link name="right_hand_v3_ring_middle_link">
    <inertial>
      <mass value="0.0034433482"/>
      <inertia ixx="5.9259154e-08" ixy="4.7090997e-09" ixz="0" iyy="4.384944e-07" iyz="0" izz="4.5043748e-07"/>
      <origin rpy="0 0 0" xyz="8.2958878e-03 1.4867666e-04 0"/>
    </inertial>
    <visual>
      <origin rpy="0 0 0" xyz="0 0 0"/>
      <geometry>
        <mesh filename="package://softhands_description/meshes/v3/right/ph_proximal.stl" scale="0.001 0.001 0.001"/>
      </geometry>
      <material name="qbhand/palm"/>
    </visual>
    <collision>
      <origin rpy="0 0 0" xyz="0 0 0"/>
      <geometry>
        <mesh filename="package://softhands_description/meshes/v3/right/ph_proximal_collision.stl" scale="0.001 0.001 0.001"/>
      </geometry>
    </collision>
  </link>
  <!-- GAZEBO REF -->
  <gazebo reference="right_hand_v3_ring_middle_link">
    <material>Gazebo/Grey</material>
    <selfCollide>0</selfCollide>
  </gazebo>
  <!-- GAZEBO REF -->
  <gazebo reference="right_hand_v3_ring_middle_virtual_link">
    <material>Gazebo/Grey</material>
    <selfCollide>0</selfCollide>
  </gazebo>
  <!-- GAZEBO REF -->
  <gazebo reference="right_hand_v3_ring_middle_joint">
    <implicitSpringDamper>true</implicitSpringDamper>
    <springStiffness>0.4</springStiffness>
    <springReference>0</springReference>
  </gazebo>
  <!-- GAZEBO REF -->
  <gazebo reference="right_hand_v3_ring_middle_virtual_joint">
    <implicitSpringDamper>true</implicitSpringDamper>
    <springStiffness>0.4</springStiffness>
    <springReference>0</springReference>
  </gazebo>
  <!-- Inner VIRTUAL JOINT -->
  <joint name="right_hand_v3_ring_distal_virtual_joint" type="revolute">
    <axis xyz="0 0 -1"/>
    <origin rpy="0 0 0" xyz="16e-03 0 0"/>
    <parent link="right_hand_v3_ring_middle_link"/>
    <child link="right_hand_v3_ring_distal_virtual_link"/>
    <limit effort="30" lower="0.0" upper="0.785398" velocity="10.0"/>
    <dynamics damping="0.05" friction="0.1"/>
  </joint>
  <!-- VIRTUAL LINK -->
  <link name="right_hand_v3_ring_distal_virtual_link">
    <inertial>
      <origin rpy="0 0 0" xyz="0 0 0"/>
      <mass value="0.0024034657"/>
      <inertia ixx="2.9487712e-08" ixy="5.9094481e-10" ixz="1.3105246e-10" iyy="6.1647801e-08" iyz="4.9617465e-11" izz="5.8551334e-08"/>
    </inertial>
  </link>
  <!-- Outer JOINT -->
  <joint name="right_hand_v3_ring_distal_joint" type="revolute">
    <axis xyz="0 0 -1"/>
    <origin rpy="0 0 0" xyz="10e-03 -0.000348650e-03 0.5e-03"/>
    <parent link="right_hand_v3_ring_distal_virtual_link"/>
    <child link="right_hand_v3_ring_distal_link"/>
    <limit effort="30" lower="0.0" upper="0.785398" velocity="10.0"/>
    <dynamics damping="0.05" friction="0.1"/>
  </joint>
  <!-- LINK -->
  <link name="right_hand_v3_ring_distal_link">
    <inertial>
      <mass value="0.0024034657"/>
      <inertia ixx="2.9487712e-08" ixy="5.9094481e-10" ixz="1.3105246e-10" iyy="6.1647801e-08" iyz="4.9617465e-11" izz="5.8551334e-08"/>
      <origin rpy="0 0 0" xyz="2.3379604e-03 5.3580065e-04 -4.5070160e-04"/>
    </inertial>
    <visual>
      <origin rpy="0 0 0" xyz="0 0 0"/>
      <geometry>
        <mesh filename="package://softhands_description/meshes/v3/right/ph_distal.stl" scale="0.001 0.001 0.001"/>
      </geometry>
      <material name="qbhand/palm"/>
    </visual>
    <collision>
      <origin rpy="0 0 0" xyz="0 0 0"/>
      <geometry>
        <mesh filename="package://softhands_description/meshes/v3/right/ph_distal_collision.stl" scale="0.001 0.001 0.001"/>
      </geometry>
    </collision>
  </link>
  <!-- GAZEBO REF -->
  <gazebo reference="right_hand_v3_ring_distal_link">
    <material>Gazebo/Grey</material>
    <selfCollide>0</selfCollide>
  </gazebo>
  <!-- GAZEBO REF -->
  <gazebo reference="right_hand_v3_ring_distal_virtual_link">
    <material>Gazebo/Grey</material>
    <selfCollide>0</selfCollide>
  </gazebo>
  <!-- GAZEBO REF -->
  <gazebo reference="right_hand_v3_ring_distal_joint">
    <implicitSpringDamper>true</implicitSpringDamper>
    <springStiffness>0.4</springStiffness>
    <springReference>0</springReference>
  </gazebo>
  <!-- GAZEBO REF -->
  <gazebo reference="right_hand_v3_ring_distal_virtual_joint">
    <implicitSpringDamper>true</implicitSpringDamper>
    <springStiffness>0.4</springStiffness>
    <springReference>0</springReference>
  </gazebo>
  <!-- Proximal JOINT -->
  <joint name="right_hand_v3_little_knuckle_joint" type="revolute">
    <origin rpy="0 0 1.3089971" xyz="37e-03 -5e-03 6.02670e-03"/>
    <parent link="right_hand_v3_palm_link"/>
    <child link="right_hand_v3_little_knuckle_link"/>
    <axis xyz="0 0 -1"/>
    <limit effort="30" lower="-0.524" upper="0.524" velocity="10.0"/>
    <dynamics damping="0.05" friction="0.1"/>
  </joint>
  <!-- LINK -->
  <link name="right_hand_v3_little_knuckle_link">
    <inertial>
      <mass value="0.0043252792"/>
      <inertia ixx="8.3644527e-08" ixy="-4.5618254e-08" ixz="2.3871797e-09" iyy="2.5669244e-07" iyz="8.8656059e-10" izz="2.4876038e-07"/>
      <origin rpy="0 0 0" xyz="5.6446671e-03 1.8762438e-03 1.1508432e-04"/>
    </inertial>
    <visual>
      <origin rpy="0 0 0" xyz="0 0 0"/>
      <geometry>
        <mesh filename="package://softhands_description/meshes/v3/right/ph_ring_knuckle.stl" scale="0.001 0.001 0.001"/>
      </geometry>
      <material name="qbhand/palm"/>
    </visual>
    <collision>
      <origin rpy="0 0 0" xyz="0 0 0"/>
      <geometry>
        <mesh filename="package://softhands_description/meshes/v3/right/ph_ring_knuckle_collision.stl" scale="0.001 0.001 0.001"/>
      </geometry>
    </collision>
  </link>
  <!-- GAZEBO REF -->
  <gazebo reference="right_hand_v3_little_knuckle_link">
    <material>Gazebo/Grey</material>
    <selfCollide>0</selfCollide>
  </gazebo>
  <!-- GAZEBO REF -->
  <gazebo reference="right_hand_v3_little_knuckle_joint">
    <implicitSpringDamper>true</implicitSpringDamper>
    <springStiffness>0.8</springStiffness>
    <springReference>0</springReference>
  </gazebo>
  <!-- Inner VIRTUAL JOINT -->
  <joint name="right_hand_v3_little_proximal_virtual_joint" type="revolute">
    <axis xyz="0 0 -1"/>
    <origin rpy="1.5707963 0 0" xyz="15e-03 3.7e-03 0"/>
    <parent link="right_hand_v3_little_knuckle_link"/>
    <child link="right_hand_v3_little_proximal_virtual_link"/>
    <limit effort="30" lower="0.0" upper="0.785398" velocity="10.0"/>
    <dynamics damping="0.05" friction="0.1"/>
  </joint>
  <!-- VIRTUAL LINK -->
  <link name="right_hand_v3_little_proximal_virtual_link">
    <inertial>
      <origin rpy="0 0 0" xyz="0 0 0"/>
      <mass value="0.0036325256"/>
      <inertia ixx="5.2310988e-08" ixy="2.9585316e-09" ixz="0" iyy="1.5555268e-07" iyz="0" izz="1.568955e-07"/>
    </inertial>
  </link>
  <!-- Outer JOINT -->
  <joint name="right_hand_v3_little_proximal_joint" type="revolute">
    <axis xyz="0 0 -1"/>
    <origin rpy="0 0 0" xyz="10e-03 0 0"/>
    <parent link="right_hand_v3_little_proximal_virtual_link"/>
    <child link="right_hand_v3_little_proximal_link"/>
    <limit effort="30" lower="0.0" upper="0.785398" velocity="10.0"/>
    <dynamics damping="0.05" friction="0.1"/>
  </joint>
  <!-- LINK -->
  <link name="right_hand_v3_little_proximal_link">
    <inertial>
      <mass value="0.0036325256"/>
      <inertia ixx="5.2310988e-08" ixy="2.9585316e-09" ixz="0" iyy="1.5555268e-07" iyz="0" izz="1.568955e-07"/>
      <origin rpy="0 0 0" xyz="4.8712343e-03 1.5590106e-04 0"/>
    </inertial>
    <visual>
      <origin rpy="0 0 0" xyz="0 0 0"/>
      <geometry>
        <mesh filename="package://softhands_description/meshes/v3/right/ph_proximal_little.stl" scale="0.001 0.001 0.001"/>
      </geometry>
      <material name="qbhand/palm"/>
    </visual>
    <collision>
      <origin rpy="0 0 0" xyz="0 0 0"/>
      <geometry>
        <mesh filename="package://softhands_description/meshes/v3/right/ph_proximal_little_collision.stl" scale="0.001 0.001 0.001"/>
      </geometry>
    </collision>
  </link>
  <!-- GAZEBO REF -->
  <gazebo reference="right_hand_v3_little_proximal_link">
    <material>Gazebo/Grey</material>
    <selfCollide>0</selfCollide>
  </gazebo>
  <!-- GAZEBO REF -->
  <gazebo reference="right_hand_v3_little_proximal_virtual_link">
    <material>Gazebo/Grey</material>
    <selfCollide>0</selfCollide>
  </gazebo>
  <!-- GAZEBO REF -->
  <gazebo reference="right_hand_v3_little_proximal_joint">
    <implicitSpringDamper>true</implicitSpringDamper>
    <springStiffness>0.4</springStiffness>
    <springReference>0</springReference>
  </gazebo>
  <!-- GAZEBO REF -->
  <gazebo reference="right_hand_v3_little_proximal_virtual_joint">
    <implicitSpringDamper>true</implicitSpringDamper>
    <springStiffness>0.4</springStiffness>
    <springReference>0</springReference>
  </gazebo>
  <!-- Inner VIRTUAL JOINT -->
  <joint name="right_hand_v3_little_middle_virtual_joint" type="revolute">
    <axis xyz="0 0 -1"/>
    <origin rpy="0 0 0" xyz="12e-03 0 0"/>
    <parent link="right_hand_v3_little_proximal_link"/>
    <child link="right_hand_v3_little_middle_virtual_link"/>
    <limit effort="30" lower="0.0" upper="0.785398" velocity="10.0"/>
    <dynamics damping="0.05" friction="0.1"/>
  </joint>
  <!-- VIRTUAL LINK -->
  <link name="right_hand_v3_little_middle_virtual_link">
    <inertial>
      <origin rpy="0 0 0" xyz="0 0 0"/>
      <mass value="0.0036325256"/>
      <inertia ixx="5.2310988e-08" ixy="2.9585316e-09" ixz="0" iyy="1.5555268e-07" iyz="0" izz="1.568955e-07"/>
    </inertial>
  </link>
  <!-- Outer JOINT -->
  <joint name="right_hand_v3_little_middle_joint" type="revolute">
    <axis xyz="0 0 -1"/>
    <origin rpy="0 0 0" xyz="10e-03 0 0"/>
    <parent link="right_hand_v3_little_middle_virtual_link"/>
    <child link="right_hand_v3_little_middle_link"/>
    <limit effort="30" lower="0.0" upper="0.785398" velocity="10.0"/>
    <dynamics damping="0.05" friction="0.1"/>
  </joint>
  <!-- LINK -->
  <link name="right_hand_v3_little_middle_link">
    <inertial>
      <mass value="0.0036325256"/>
      <inertia ixx="5.2310988e-08" ixy="2.9585316e-09" ixz="0" iyy="1.5555268e-07" iyz="0" izz="1.568955e-07"/>
      <origin rpy="0 0 0" xyz="4.8712343e-03 1.5590106e-04 0"/>
    </inertial>
    <visual>
      <origin rpy="0 0 0" xyz="0 0 0"/>
      <geometry>
        <mesh filename="package://softhands_description/meshes/v3/right/ph_proximal_little.stl" scale="0.001 0.001 0.001"/>
      </geometry>
      <material name="qbhand/palm"/>
    </visual>
    <collision>
      <origin rpy="0 0 0" xyz="0 0 0"/>
      <geometry>
        <mesh filename="package://softhands_description/meshes/v3/right/ph_proximal_little_collision.stl" scale="0.001 0.001 0.001"/>
      </geometry>
    </collision>
  </link>
  <!-- GAZEBO REF -->
  <gazebo reference="right_hand_v3_little_middle_link">
    <material>Gazebo/Grey</material>
    <selfCollide>0</selfCollide>
  </gazebo>
  <!-- GAZEBO REF -->
  <gazebo reference="right_hand_v3_little_middle_virtual_link">
    <material>Gazebo/Grey</material>
    <selfCollide>0</selfCollide>
  </gazebo>
  <!-- GAZEBO REF -->
  <gazebo reference="right_hand_v3_little_middle_joint">
    <implicitSpringDamper>true</implicitSpringDamper>
    <springStiffness>0.4</springStiffness>
    <springReference>0</springReference>
  </gazebo>
  <!-- GAZEBO REF -->
  <gazebo reference="right_hand_v3_little_middle_virtual_joint">
    <implicitSpringDamper>true</implicitSpringDamper>
    <springStiffness>0.4</springStiffness>
    <springReference>0</springReference>
  </gazebo>
  <!-- Inner VIRTUAL JOINT -->
  <joint name="right_hand_v3_little_distal_virtual_joint" type="revolute">
    <axis xyz="0 0 -1"/>
    <origin rpy="0 0 0" xyz="12e-03 0 0"/>
    <parent link="right_hand_v3_little_middle_link"/>
    <child link="right_hand_v3_little_distal_virtual_link"/>
    <limit effort="30" lower="0.0" upper="0.785398" velocity="10.0"/>
    <dynamics damping="0.05" friction="0.1"/>
  </joint>
  <!-- VIRTUAL LINK -->
  <link name="right_hand_v3_little_distal_virtual_link">
    <inertial>
      <origin rpy="0 0 0" xyz="0 0 0"/>
      <mass value="0.0024034657"/>
      <inertia ixx="2.9487712e-08" ixy="5.9094481e-10" ixz="1.3105246e-10" iyy="6.1647801e-08" iyz="4.9617465e-11" izz="5.8551334e-08"/>
    </inertial>
  </link>
  <!-- Outer JOINT -->
  <joint name="right_hand_v3_little_distal_joint" type="revolute">
    <axis xyz="0 0 -1"/>
    <origin rpy="0 0 0" xyz="10e-03 -0.000348650e-03 0.5e-03"/>
    <parent link="right_hand_v3_little_distal_virtual_link"/>
    <child link="right_hand_v3_little_distal_link"/>
    <limit effort="30" lower="0.0" upper="0.785398" velocity="10.0"/>
    <dynamics damping="0.05" friction="0.1"/>
  </joint>
  <!-- LINK -->
  <link name="right_hand_v3_little_distal_link">
    <inertial>
      <mass value="0.0024034657"/>
      <inertia ixx="2.9487712e-08" ixy="5.9094481e-10" ixz="1.3105246e-10" iyy="6.1647801e-08" iyz="4.9617465e-11" izz="5.8551334e-08"/>
      <origin rpy="0 0 0" xyz="2.3379604e-03 5.3580065e-04 -4.5070160e-04"/>
    </inertial>
    <visual>
      <origin rpy="0 0 0" xyz="0 0 0"/>
      <geometry>
        <mesh filename="package://softhands_description/meshes/v3/right/ph_distal.stl" scale="0.001 0.001 0.001"/>
      </geometry>
      <material name="qbhand/palm"/>
    </visual>
    <collision>
      <origin rpy="0 0 0" xyz="0 0 0"/>
      <geometry>
        <mesh filename="package://softhands_description/meshes/v3/right/ph_distal_collision.stl" scale="0.001 0.001 0.001"/>
      </geometry>
    </collision>
  </link>
  <!-- GAZEBO REF -->
  <gazebo reference="right_hand_v3_little_distal_link">
    <material>Gazebo/Grey</material>
    <selfCollide>0</selfCollide>
  </gazebo>
  <!-- GAZEBO REF -->
  <gazebo reference="right_hand_v3_little_distal_virtual_link">
    <material>Gazebo/Grey</material>
    <selfCollide>0</selfCollide>
  </gazebo>
  <!-- GAZEBO REF -->
  <gazebo reference="right_hand_v3_little_distal_joint">
    <implicitSpringDamper>true</implicitSpringDamper>
    <springStiffness>0.4</springStiffness>
    <springReference>0</springReference>
  </gazebo>
  <!-- GAZEBO REF -->
  <gazebo reference="right_hand_v3_little_distal_virtual_joint">
    <implicitSpringDamper>true</implicitSpringDamper>
    <springStiffness>0.4</springStiffness>
    <springReference>0</springReference>
  </gazebo>
</robot>

