<mujoco model="left_softhand">
  <compiler angle="radian" meshdir="/home/esguerri/SoftHand/src/SoftHand-Plugin/softhands_description/meshes/v1_2_research/left/"/>
  <asset>
    <mesh name="flange_iso_04" file="flange_iso_04.stl" scale="0.001 0.001 0.001"/>
    <mesh name="palm_pinch" file="palm_pinch.stl" scale="0.001 0.001 0.001"/>
    <mesh name="ph_thumb" file="ph_thumb.stl" scale="0.001 0.001 0.001"/>
    <mesh name="ph_short" file="ph_short.stl" scale="0.001 0.001 0.001"/>
    <mesh name="ph_distal" file="ph_distal.stl" scale="0.001 0.001 0.001"/>
    <mesh name="ph_knuckle" file="ph_knuckle.stl" scale="0.001 0.001 0.001"/>
    <mesh name="ph_medium" file="ph_medium.stl" scale="0.001 0.001 0.001"/>
  </asset>
  <worldbody>
    <geom pos="0 -0.2 0.02" quat="0.707388 0 0 -0.706825" type="mesh" contype="0" conaffinity="0" group="1" density="0" rgba="0.35 0.35 0.35 1" mesh="flange_iso_04"/>
    <geom pos="0 -0.2 0.02" quat="0.707388 0 0 -0.706825" type="mesh" rgba="0.35 0.35 0.35 1" mesh="flange_iso_04"/>
    <geom pos="0.0145036 -0.204488 0.164" quat="0.500398 0.5 0.499602 0.5" type="mesh" contype="0" conaffinity="0" group="1" density="0" rgba="0.35 0.35 0.35 1" mesh="palm_pinch"/>
    <geom pos="0.0145036 -0.204488 0.164" quat="0.500398 0.5 0.499602 0.5" type="mesh" rgba="0.35 0.35 0.35 1" mesh="palm_pinch"/>
    <body name="left_hand_v1_2_research_thumb_knuckle_link" pos="0.0165056 -0.24849 0.117502" quat="-0.706261 -0.000562864 0.000563312 0.707951">
      <inertial pos="0.0130716 0.00273463 0.000640905" quat="0.531453 0.364062 0.576479 0.502681" mass="0.01" diaginertia="1.4342e-06 1.35762e-06 3.12515e-07"/>
      <joint name="left_hand_v1_2_research_thumb_knuckle_joint" pos="0 0 0" axis="0 0 1" range="0 1.57" actuatorfrcrange="-30 30" damping="0.03"/>
      <geom type="mesh" contype="0" conaffinity="0" group="1" density="0" rgba="0.35 0.35 0.35 1" mesh="ph_thumb"/>
      <geom type="mesh" rgba="0.35 0.35 0.35 1" mesh="ph_thumb"/>
      <body name="left_hand_v1_2_research_thumb_proximal_virtual_link" pos="0.0255 0.0038 -0.00012" quat="0.540302 -0.841471 0 0">
        <inertial pos="0 0 0" quat="0.0365143 0.706163 -0.0365143 0.706163" mass="0.0063" diaginertia="2.6915e-07 2.3576e-07 1.79645e-07"/>
        <joint name="left_hand_v1_2_research_thumb_proximal_virtual_joint" pos="0 0 0" axis="0 0 -1" range="0 0.785398" actuatorfrcrange="-30 30" damping="0.03"/>
        <body name="left_hand_v1_2_research_thumb_proximal_link" pos="0.013 0 0">
          <inertial pos="0.00476016 -0.00137869 0" quat="0.0365143 0.706163 -0.0365143 0.706163" mass="0.0063" diaginertia="2.6915e-07 2.3576e-07 1.79645e-07"/>
          <joint name="left_hand_v1_2_research_thumb_proximal_joint" pos="0 0 0" axis="0 0 -1" range="0 0.785398" actuatorfrcrange="-30 30" damping="0.03"/>
          <geom type="mesh" contype="0" conaffinity="0" group="1" density="0" rgba="0.35 0.35 0.35 1" mesh="ph_short"/>
          <geom type="mesh" rgba="0.35 0.35 0.35 1" mesh="ph_short"/>
          <body name="left_hand_v1_2_research_thumb_distal_virtual_link" pos="0.009 0 0">
            <inertial pos="0 0 0" quat="0.0131386 0.706985 -0.0131386 0.706985" mass="0.009" diaginertia="6.6782e-07 5.99819e-07 2.654e-07"/>
            <joint name="left_hand_v1_2_research_thumb_distal_virtual_joint" pos="0 0 0" axis="0 0 -1" range="0 0.785398" actuatorfrcrange="-30 30" damping="0.03"/>
            <body name="left_hand_v1_2_research_thumb_distal_link" pos="0.013 0 0">
              <inertial pos="0.00880255 -0.00172193 0" quat="0.0131386 0.706985 -0.0131386 0.706985" mass="0.009" diaginertia="6.6782e-07 5.99819e-07 2.654e-07"/>
              <joint name="left_hand_v1_2_research_thumb_distal_joint" pos="0 0 0" axis="0 0 -1" range="0 0.785398" actuatorfrcrange="-30 30" damping="0.03"/>
              <geom type="mesh" contype="0" conaffinity="0" group="1" density="0" rgba="0.35 0.35 0.35 1" mesh="ph_distal"/>
              <geom type="mesh" rgba="0.35 0.35 0.35 1" mesh="ph_distal"/>
            </body>
          </body>
        </body>
      </body>
    </body>
    <body name="left_hand_v1_2_research_index_knuckle_link" pos="0.000493236 -0.224477 0.156989" quat="-0.706261 4.48223e-07 0.707951 0.000562864">
      <inertial pos="0.000427536 0 -0.00143217" quat="0.587164 0.394003 0.394003 0.587164" mass="0.0095" diaginertia="1.12538e-06 7.39498e-07 6.27245e-07"/>
      <joint name="left_hand_v1_2_research_index_knuckle_joint" pos="0 0 0" axis="0 0 -1" range="-0.524 0.524" actuatorfrcrange="-30 30" damping="0.03"/>
      <geom type="mesh" contype="0" conaffinity="0" group="1" density="0" rgba="0.35 0.35 0.35 1" mesh="ph_knuckle"/>
      <geom type="mesh" rgba="0.35 0.35 0.35 1" mesh="ph_knuckle"/>
      <body name="left_hand_v1_2_research_index_proximal_virtual_link" pos="0.009 0 0" quat="0.707388 0.706825 0 0">
        <inertial pos="0 0 0" quat="0.0123083 0.707 -0.0123083 0.707" mass="0.009" diaginertia="5.95622e-07 5.59876e-07 2.26817e-07"/>
        <joint name="left_hand_v1_2_research_index_proximal_virtual_joint" pos="0 0 0" axis="0 0 -1" range="0 0.785398" actuatorfrcrange="-30 30" damping="0.03"/>
        <body name="left_hand_v1_2_research_index_proximal_link" pos="0.013 0 0">
          <inertial pos="0.00877074 -0.00178631 0" quat="0.0123083 0.707 -0.0123083 0.707" mass="0.009" diaginertia="5.95622e-07 5.59876e-07 2.26817e-07"/>
          <joint name="left_hand_v1_2_research_index_proximal_joint" pos="0 0 0" axis="0 0 -1" range="0 0.785398" actuatorfrcrange="-30 30" damping="0.03"/>
          <geom type="mesh" contype="0" conaffinity="0" group="1" density="0" rgba="0.35 0.35 0.35 1" mesh="ph_medium"/>
          <geom type="mesh" rgba="0.35 0.35 0.35 1" mesh="ph_medium"/>
          <body name="left_hand_v1_2_research_index_middle_virtual_link" pos="0.013 0 0">
            <inertial pos="0 0 0" quat="0.0365143 0.706163 -0.0365143 0.706163" mass="0.0063" diaginertia="2.6915e-07 2.3576e-07 1.79645e-07"/>
            <joint name="left_hand_v1_2_research_index_middle_virtual_joint" pos="0 0 0" axis="0 0 -1" range="0 0.785398" actuatorfrcrange="-30 30" damping="0.03"/>
            <body name="left_hand_v1_2_research_index_middle_link" pos="0.017 0 0">
              <inertial pos="0.00476016 -0.00137869 0" quat="0.0365143 0.706163 -0.0365143 0.706163" mass="0.0063" diaginertia="2.6915e-07 2.3576e-07 1.79645e-07"/>
              <joint name="left_hand_v1_2_research_index_middle_joint" pos="0 0 0" axis="0 0 -1" range="0 0.785398" actuatorfrcrange="-30 30" damping="0.03"/>
              <geom type="mesh" contype="0" conaffinity="0" group="1" density="0" rgba="0.35 0.35 0.35 1" mesh="ph_short"/>
              <geom type="mesh" rgba="0.35 0.35 0.35 1" mesh="ph_short"/>
              <body name="left_hand_v1_2_research_index_distal_virtual_link" pos="0.009 0 0">
                <inertial pos="0 0 0" quat="0.0131386 0.706985 -0.0131386 0.706985" mass="0.009" diaginertia="6.6782e-07 5.99819e-07 2.654e-07"/>
                <joint name="left_hand_v1_2_research_index_distal_virtual_joint" pos="0 0 0" axis="0 0 -1" range="0 0.785398" actuatorfrcrange="-30 30" damping="0.03"/>
                <body name="left_hand_v1_2_research_index_distal_link" pos="0.013 0 0">
                  <inertial pos="0.00880255 -0.00172193 0" quat="0.0131386 0.706985 -0.0131386 0.706985" mass="0.009" diaginertia="6.6782e-07 5.99819e-07 2.654e-07"/>
                  <joint name="left_hand_v1_2_research_index_distal_joint" pos="0 0 0" axis="0 0 -1" range="0 0.785398" actuatorfrcrange="-30 30" damping="0.03"/>
                  <geom type="mesh" contype="0" conaffinity="0" group="1" density="0" rgba="0.35 0.35 0.35 1" mesh="ph_distal"/>
                  <geom type="mesh" rgba="0.35 0.35 0.35 1" mesh="ph_distal"/>
                </body>
              </body>
            </body>
          </body>
        </body>
      </body>
    </body>
    <body name="left_hand_v1_2_research_middle_knuckle_link" pos="0.000503588 -0.204477 0.163989" quat="-0.706261 4.48223e-07 0.707951 0.000562864">
      <inertial pos="0.000427536 0 -0.00143217" quat="0.587164 0.394003 0.394003 0.587164" mass="0.0095" diaginertia="1.12538e-06 7.39498e-07 6.27245e-07"/>
      <joint name="left_hand_v1_2_research_middle_knuckle_joint" pos="0 0 0" axis="0 0 -1" range="-0.524 0.524" actuatorfrcrange="-30 30" damping="0.03"/>
      <geom type="mesh" contype="0" conaffinity="0" group="1" density="0" rgba="0.35 0.35 0.35 1" mesh="ph_knuckle"/>
      <geom type="mesh" rgba="0.35 0.35 0.35 1" mesh="ph_knuckle"/>
      <body name="left_hand_v1_2_research_middle_proximal_virtual_link" pos="0.009 0 0" quat="0.707388 0.706825 0 0">
        <inertial pos="0 0 0" quat="0.0123083 0.707 -0.0123083 0.707" mass="0.009" diaginertia="5.95622e-07 5.59876e-07 2.26817e-07"/>
        <joint name="left_hand_v1_2_research_middle_proximal_virtual_joint" pos="0 0 0" axis="0 0 -1" range="0 0.785398" actuatorfrcrange="-30 30" damping="0.03"/>
        <body name="left_hand_v1_2_research_middle_proximal_link" pos="0.013 0 0">
          <inertial pos="0.00877074 -0.00178631 0" quat="0.0123083 0.707 -0.0123083 0.707" mass="0.009" diaginertia="5.95622e-07 5.59876e-07 2.26817e-07"/>
          <joint name="left_hand_v1_2_research_middle_proximal_joint" pos="0 0 0" axis="0 0 -1" range="0 0.785398" actuatorfrcrange="-30 30" damping="0.03"/>
          <geom type="mesh" contype="0" conaffinity="0" group="1" density="0" rgba="0.35 0.35 0.35 1" mesh="ph_medium"/>
          <geom type="mesh" rgba="0.35 0.35 0.35 1" mesh="ph_medium"/>
          <body name="left_hand_v1_2_research_middle_middle_virtual_link" pos="0.013 0 0">
            <inertial pos="0 0 0" quat="0.0365143 0.706163 -0.0365143 0.706163" mass="0.0063" diaginertia="2.6915e-07 2.3576e-07 1.79645e-07"/>
            <joint name="left_hand_v1_2_research_middle_middle_virtual_joint" pos="0 0 0" axis="0 0 -1" range="0 0.785398" actuatorfrcrange="-30 30" damping="0.03"/>
            <body name="left_hand_v1_2_research_middle_middle_link" pos="0.017 0 0">
              <inertial pos="0.00476016 -0.00137869 0" quat="0.0365143 0.706163 -0.0365143 0.706163" mass="0.0063" diaginertia="2.6915e-07 2.3576e-07 1.79645e-07"/>
              <joint name="left_hand_v1_2_research_middle_middle_joint" pos="0 0 0" axis="0 0 -1" range="0 0.785398" actuatorfrcrange="-30 30" damping="0.03"/>
              <geom type="mesh" contype="0" conaffinity="0" group="1" density="0" rgba="0.35 0.35 0.35 1" mesh="ph_short"/>
              <geom type="mesh" rgba="0.35 0.35 0.35 1" mesh="ph_short"/>
              <body name="left_hand_v1_2_research_middle_distal_virtual_link" pos="0.009 0 0">
                <inertial pos="0 0 0" quat="0.0131386 0.706985 -0.0131386 0.706985" mass="0.009" diaginertia="6.6782e-07 5.99819e-07 2.654e-07"/>
                <joint name="left_hand_v1_2_research_middle_distal_virtual_joint" pos="0 0 0" axis="0 0 -1" range="0 0.785398" actuatorfrcrange="-30 30" damping="0.03"/>
                <body name="left_hand_v1_2_research_middle_distal_link" pos="0.013 0 0">
                  <inertial pos="0.00880255 -0.00172193 0" quat="0.0131386 0.706985 -0.0131386 0.706985" mass="0.009" diaginertia="6.6782e-07 5.99819e-07 2.654e-07"/>
                  <joint name="left_hand_v1_2_research_middle_distal_joint" pos="0 0 0" axis="0 0 -1" range="0 0.785398" actuatorfrcrange="-30 30" damping="0.03"/>
                  <geom type="mesh" contype="0" conaffinity="0" group="1" density="0" rgba="0.35 0.35 0.35 1" mesh="ph_distal"/>
                  <geom type="mesh" rgba="0.35 0.35 0.35 1" mesh="ph_distal"/>
                </body>
              </body>
            </body>
          </body>
        </body>
      </body>
    </body>
    <body name="left_hand_v1_2_research_ring_knuckle_link" pos="0.000525089 -0.184477 0.156989" quat="-0.706261 4.48223e-07 0.707951 0.000562864">
      <inertial pos="0.000427536 0 -0.00143217" quat="0.587164 0.394003 0.394003 0.587164" mass="0.0095" diaginertia="1.12538e-06 7.39498e-07 6.27245e-07"/>
      <joint name="left_hand_v1_2_research_ring_knuckle_joint" pos="0 0 0" axis="0 0 -1" range="-0.524 0.524" actuatorfrcrange="-30 30" damping="0.03"/>
      <geom type="mesh" contype="0" conaffinity="0" group="1" density="0" rgba="0.35 0.35 0.35 1" mesh="ph_knuckle"/>
      <geom type="mesh" rgba="0.35 0.35 0.35 1" mesh="ph_knuckle"/>
      <body name="left_hand_v1_2_research_ring_proximal_virtual_link" pos="0.009 0 0" quat="0.707388 0.706825 0 0">
        <inertial pos="0 0 0" quat="0.0123083 0.707 -0.0123083 0.707" mass="0.009" diaginertia="5.95622e-07 5.59876e-07 2.26817e-07"/>
        <joint name="left_hand_v1_2_research_ring_proximal_virtual_joint" pos="0 0 0" axis="0 0 -1" range="0 0.785398" actuatorfrcrange="-30 30" damping="0.03"/>
        <body name="left_hand_v1_2_research_ring_proximal_link" pos="0.013 0 0">
          <inertial pos="0.00877074 -0.00178631 0" quat="0.0123083 0.707 -0.0123083 0.707" mass="0.009" diaginertia="5.95622e-07 5.59876e-07 2.26817e-07"/>
          <joint name="left_hand_v1_2_research_ring_proximal_joint" pos="0 0 0" axis="0 0 -1" range="0 0.785398" actuatorfrcrange="-30 30" damping="0.03"/>
          <geom type="mesh" contype="0" conaffinity="0" group="1" density="0" rgba="0.35 0.35 0.35 1" mesh="ph_medium"/>
          <geom type="mesh" rgba="0.35 0.35 0.35 1" mesh="ph_medium"/>
          <body name="left_hand_v1_2_research_ring_middle_virtual_link" pos="0.013 0 0">
            <inertial pos="0 0 0" quat="0.0365143 0.706163 -0.0365143 0.706163" mass="0.0063" diaginertia="2.6915e-07 2.3576e-07 1.79645e-07"/>
            <joint name="left_hand_v1_2_research_ring_middle_virtual_joint" pos="0 0 0" axis="0 0 -1" range="0 0.785398" actuatorfrcrange="-30 30" damping="0.03"/>
            <body name="left_hand_v1_2_research_ring_middle_link" pos="0.017 0 0">
              <inertial pos="0.00476016 -0.00137869 0" quat="0.0365143 0.706163 -0.0365143 0.706163" mass="0.0063" diaginertia="2.6915e-07 2.3576e-07 1.79645e-07"/>
              <joint name="left_hand_v1_2_research_ring_middle_joint" pos="0 0 0" axis="0 0 -1" range="0 0.785398" actuatorfrcrange="-30 30" damping="0.03"/>
              <geom type="mesh" contype="0" conaffinity="0" group="1" density="0" rgba="0.35 0.35 0.35 1" mesh="ph_short"/>
              <geom type="mesh" rgba="0.35 0.35 0.35 1" mesh="ph_short"/>
              <body name="left_hand_v1_2_research_ring_distal_virtual_link" pos="0.009 0 0">
                <inertial pos="0 0 0" quat="0.0131386 0.706985 -0.0131386 0.706985" mass="0.009" diaginertia="6.6782e-07 5.99819e-07 2.654e-07"/>
                <joint name="left_hand_v1_2_research_ring_distal_virtual_joint" pos="0 0 0" axis="0 0 -1" range="0 0.785398" actuatorfrcrange="-30 30" damping="0.03"/>
                <body name="left_hand_v1_2_research_ring_distal_link" pos="0.013 0 0">
                  <inertial pos="0.00880255 -0.00172193 0" quat="0.0131386 0.706985 -0.0131386 0.706985" mass="0.009" diaginertia="6.6782e-07 5.99819e-07 2.654e-07"/>
                  <joint name="left_hand_v1_2_research_ring_distal_joint" pos="0 0 0" axis="0 0 -1" range="0 0.785398" actuatorfrcrange="-30 30" damping="0.03"/>
                  <geom type="mesh" contype="0" conaffinity="0" group="1" density="0" rgba="0.35 0.35 0.35 1" mesh="ph_distal"/>
                  <geom type="mesh" rgba="0.35 0.35 0.35 1" mesh="ph_distal"/>
                </body>
              </body>
            </body>
          </body>
        </body>
      </body>
    </body>
    <body name="left_hand_v1_2_research_little_knuckle_link" pos="0.000544997 -0.164477 0.151989" quat="-0.706261 4.48223e-07 0.707951 0.000562864">
      <inertial pos="0.000427536 0 -0.00143217" quat="0.587164 0.394003 0.394003 0.587164" mass="0.0095" diaginertia="1.12538e-06 7.39498e-07 6.27245e-07"/>
      <joint name="left_hand_v1_2_research_little_knuckle_joint" pos="0 0 0" axis="0 0 -1" range="-0.524 0.524" actuatorfrcrange="-30 30" damping="0.03"/>
      <geom type="mesh" contype="0" conaffinity="0" group="1" density="0" rgba="0.35 0.35 0.35 1" mesh="ph_knuckle"/>
      <geom type="mesh" rgba="0.35 0.35 0.35 1" mesh="ph_knuckle"/>
      <body name="left_hand_v1_2_research_little_proximal_virtual_link" pos="0.009 0 0" quat="0.707388 0.706825 0 0">
        <inertial pos="0 0 0" quat="0.0123083 0.707 -0.0123083 0.707" mass="0.009" diaginertia="5.95622e-07 5.59876e-07 2.26817e-07"/>
        <joint name="left_hand_v1_2_research_little_proximal_virtual_joint" pos="0 0 0" axis="0 0 -1" range="0 0.785398" actuatorfrcrange="-30 30" damping="0.03"/>
        <body name="left_hand_v1_2_research_little_proximal_link" pos="0.013 0 0">
          <inertial pos="0.00877074 -0.00178631 0" quat="0.0123083 0.707 -0.0123083 0.707" mass="0.009" diaginertia="5.95622e-07 5.59876e-07 2.26817e-07"/>
          <joint name="left_hand_v1_2_research_little_proximal_joint" pos="0 0 0" axis="0 0 -1" range="0 0.785398" actuatorfrcrange="-30 30" damping="0.03"/>
          <geom type="mesh" contype="0" conaffinity="0" group="1" density="0" rgba="0.35 0.35 0.35 1" mesh="ph_medium"/>
          <geom type="mesh" rgba="0.35 0.35 0.35 1" mesh="ph_medium"/>
          <body name="left_hand_v1_2_research_little_middle_virtual_link" pos="0.013 0 0">
            <inertial pos="0 0 0" quat="0.0365143 0.706163 -0.0365143 0.706163" mass="0.0063" diaginertia="2.6915e-07 2.3576e-07 1.79645e-07"/>
            <joint name="left_hand_v1_2_research_little_middle_virtual_joint" pos="0 0 0" axis="0 0 -1" range="0 0.785398" actuatorfrcrange="-30 30" damping="0.03"/>
            <body name="left_hand_v1_2_research_little_middle_link" pos="0.017 0 0">
              <inertial pos="0.00476016 -0.00137869 0" quat="0.0365143 0.706163 -0.0365143 0.706163" mass="0.0063" diaginertia="2.6915e-07 2.3576e-07 1.79645e-07"/>
              <joint name="left_hand_v1_2_research_little_middle_joint" pos="0 0 0" axis="0 0 -1" range="0 0.785398" actuatorfrcrange="-30 30" damping="0.03"/>
              <geom type="mesh" contype="0" conaffinity="0" group="1" density="0" rgba="0.35 0.35 0.35 1" mesh="ph_short"/>
              <geom type="mesh" rgba="0.35 0.35 0.35 1" mesh="ph_short"/>
              <body name="left_hand_v1_2_research_little_distal_virtual_link" pos="0.009 0 0">
                <inertial pos="0 0 0" quat="0.0131386 0.706985 -0.0131386 0.706985" mass="0.009" diaginertia="6.6782e-07 5.99819e-07 2.654e-07"/>
                <joint name="left_hand_v1_2_research_little_distal_virtual_joint" pos="0 0 0" axis="0 0 -1" range="0 0.785398" actuatorfrcrange="-30 30" damping="0.03"/>
                <body name="left_hand_v1_2_research_little_distal_link" pos="0.013 0 0">
                  <inertial pos="0.00880255 -0.00172193 0" quat="0.0131386 0.706985 -0.0131386 0.706985" mass="0.009" diaginertia="6.6782e-07 5.99819e-07 2.654e-07"/>
                  <joint name="left_hand_v1_2_research_little_distal_joint" pos="0 0 0" axis="0 0 -1" range="0 0.785398" actuatorfrcrange="-30 30" damping="0.03"/>
                  <geom type="mesh" contype="0" conaffinity="0" group="1" density="0" rgba="0.35 0.35 0.35 1" mesh="ph_distal"/>
                  <geom type="mesh" rgba="0.35 0.35 0.35 1" mesh="ph_distal"/>
                </body>
              </body>
            </body>
          </body>
        </body>
      </body>
    </body>
  </worldbody>
</mujoco>
